<?xml version="1.0" encoding="utf-8"?>
<!-- This URDF was automatically created by SolidWorks to URDF Exporter! Originally created by Stephen Brawner (brawner@gmail.com) 
     Commit Version: 1.6.0-4-g7f85cfe  Build Version: 1.6.7995.38578
     For more information, please see http://wiki.ros.org/sw_urdf_exporter -->
<robot
  name="slip_flat">
  <link
    name="base_link">
    <inertial>
      <origin
        xyz="-2.2133E-17 7.3403E-17 -3.1225E-17"
        rpy="0 0 0" />
      <mass
        value="13.854" />
      <inertia
        ixx="0.25188"
        ixy="-8.0055E-17"
        ixz="5.5135E-18"
        iyy="1.1876"
        iyz="2.3199E-18"
        izz="1.439" />
    </inertial>
    <visual>
      <origin
        xyz="0 0 0"
        rpy="0 0 0" />
      <geometry>
        <mesh
          filename="package://slip_flat/meshes/base_link.STL" />
      </geometry>
      <material
        name="">
        <color
          rgba="0.79216 0.81961 0.93333 1" />
      </material>
    </visual>
    <collision>
      <origin
        xyz="0 0 0"
        rpy="0 0 0" />
      <geometry>
        <mesh
          filename="package://slip_flat/meshes/base_link.STL" />
      </geometry>
    </collision>
  </link>
  <link
    name="link1">
    <inertial>
      <origin
        xyz="8.3694E-16 3.4216E-17 1.2143E-17"
        rpy="0 0 0" />
      <mass
        value="0.46057" />
      <inertia
        ixx="0.001133"
        ixy="9.5536E-19"
        ixz="1.8181E-19"
        iyy="0.0025494"
        iyz="1.5617E-19"
        izz="0.0032044" />
    </inertial>
    <visual>
      <origin
        xyz="0 0 0"
        rpy="0 0 0" />
      <geometry>
        <mesh
          filename="package://slip_flat/meshes/link1.STL" />
      </geometry>
      <material
        name="">
        <color
          rgba="0.79216 0.81961 0.93333 1" />
      </material>
    </visual>
    <collision>
      <origin
        xyz="0 0 0"
        rpy="0 0 0" />
      <geometry>
        <mesh
          filename="package://slip_flat/meshes/link1.STL" />
      </geometry>
    </collision>
  </link>
  <joint
    name="joint1"
    type="revolute">
    <origin
      xyz="0 0 0"
      rpy="0 0 0" />
    <parent
      link="base_link" />
    <child
      link="link1" />
    <axis
      xyz="-1 0 0" />
    <limit
      lower="-3.14"
      upper="3.14"
      effort="100"
      velocity="1" />
  </joint>
  <link
    name="link2">
    <inertial>
      <origin
        xyz="-1.3375E-08 -2.518E-08 -0.063872"
        rpy="0 0 0" />
      <mass
        value="1.7676" />
      <inertia
        ixx="0.01034"
        ixy="-2.2581E-09"
        ixz="-2.4133E-10"
        iyy="0.010119"
        iyz="3.1353E-09"
        izz="0.0027532" />
    </inertial>
    <visual>
      <origin
        xyz="0 0 0"
        rpy="0 0 0" />
      <geometry>
        <mesh
          filename="package://slip_flat/meshes/link2.STL" />
      </geometry>
      <material
        name="">
        <color
          rgba="0.79216 0.81961 0.93333 1" />
      </material>
    </visual>
    <collision>
      <origin
        xyz="0 0 0"
        rpy="0 0 0" />
      <geometry>
        <mesh
          filename="package://slip_flat/meshes/link2.STL" />
      </geometry>
    </collision>
  </link>
  <joint
    name="joint2"
    type="revolute">
    <origin
      xyz="0 0 0"
      rpy="0 0 0" />
    <parent
      link="link1" />
    <child
      link="link2" />
    <axis
      xyz="0 -1 0" />
    <limit
      lower="-3.14"
      upper="3.14"
      effort="100"
      velocity="1" />
  </joint>
  <link
    name="toe">
    <inertial>
      <origin
        xyz="7.8283E-16 -2.1161E-16 -0.0038948"
        rpy="0 0 0" />
      <mass
        value="0.51686" />
      <inertia
        ixx="0.00050871"
        ixy="-6.5858E-22"
        ixz="8.549E-21"
        iyy="0.00050871"
        iyz="3.4524E-20"
        izz="0.00052218" />
    </inertial>
    <visual>
      <origin
        xyz="0 0 0"
        rpy="0 0 0" />
      <geometry>
        <mesh
          filename="package://slip_flat/meshes/toe.STL" />
      </geometry>
      <material
        name="">
        <color
          rgba="0.79216 0.81961 0.93333 1" />
      </material>
    </visual>
    <collision>
      <origin
        xyz="0 0 0"
        rpy="0 0 0" />
      <geometry>
        <mesh
          filename="package://slip_flat/meshes/toe.STL" />
      </geometry>
    </collision>
  </link>
  <joint
    name="joint3"
    type="prismatic">
    <origin
      xyz="0 0 -0.7"
      rpy="0 0 0" />
    <parent
      link="link2" />
    <child
      link="toe" />
    <axis
      xyz="0 0 1" />
    <limit
      lower="-0.5"
      upper="0.5"
      effort="3000"
      velocity="10" />
    <dynamics
      damping="10" />
  </joint>
</robot>